Workbook

Sheet Start
B1: Pacifica: the financial model, 1846-1932
B2: Rebuilt from the master storyline of 18 October 2026: every canon event with a cost, the approved oil, turbine and electrical programmes, a real fleet, Japan's own budget and a world comparison.
B4: Case in use | C4: =Levers!F4 -> Story case | E4: Change it on Levers, cell E4 (1 = Story, 2 = Stress).
B5: Problems found by Checks, all years | C5: =SUM(Checks!S6:S92) -> 0 | E5: Zero means every year passes the arithmetic, the canon ceilings and the story checks.
B7: Key results | C7: 1850 | D7: 1865 | E7: 1880 | F7: 1895 | G7: 1905 | H7: 1913 | I7: 1918 | J7: 1922 | K7: 1929 | L7: 1932
B8: People and economy
B9: Residents (millions) | C9: =INDEX(People!$W$6:$W$92,MATCH(C$7,People!$A$6:$A$92,0))/1000000 -> 0.35280293 | D9: =INDEX(People!$W$6:$W$92,MATCH(D$7,People!$A$6:$A$92,0))/1000000 -> 1.9005936 | E9: =INDEX(People!$W$6:$W$92,MATCH(E$7,People!$A$6:$A$92,0))/1000000 -> 4.3604186 | F9: =INDEX(People!$W$6:$W$92,MATCH(F$7,People!$A$6:$A$92,0))/1000000 -> 8.3296699 | G9: =INDEX(People!$W$6:$W$92,MATCH(G$7,People!$A$6:$A$92,0))/1000000 -> 13.195122 | H9: =INDEX(People!$W$6:$W$92,MATCH(H$7,People!$A$6:$A$92,0))/1000000 -> 19.227664 | I9: =INDEX(People!$W$6:$W$92,MATCH(I$7,People!$A$6:$A$92,0))/1000000 -> 22.891194 | J9: =INDEX(People!$W$6:$W$92,MATCH(J$7,People!$A$6:$A$92,0))/1000000 -> 26.402898 | ... L9: =INDEX(People!$W$6:$W$92,MATCH(L$7,People!$A$6:$A$92,0))/1000000 -> 36.181178
B10: Asian-origin share of residents | C10: =INDEX(People!$S$6:$S$92,MATCH(C$7,People!$A$6:$A$92,0)) -> 0.018436588 | D10: =INDEX(People!$S$6:$S$92,MATCH(D$7,People!$A$6:$A$92,0)) -> 0.10370891 | E10: =INDEX(People!$S$6:$S$92,MATCH(E$7,People!$A$6:$A$92,0)) -> 0.14290257 | F10: =INDEX(People!$S$6:$S$92,MATCH(F$7,People!$A$6:$A$92,0)) -> 0.18528421 | G10: =INDEX(People!$S$6:$S$92,MATCH(G$7,People!$A$6:$A$92,0)) -> 0.2161103 | H10: =INDEX(People!$S$6:$S$92,MATCH(H$7,People!$A$6:$A$92,0)) -> 0.23557319 | I10: =INDEX(People!$S$6:$S$92,MATCH(I$7,People!$A$6:$A$92,0)) -> 0.25247851 | J10: =INDEX(People!$S$6:$S$92,MATCH(J$7,People!$A$6:$A$92,0)) -> 0.26668688 | ... L10: =INDEX(People!$S$6:$S$92,MATCH(L$7,People!$A$6:$A$92,0)) -> 0.29441177
B11: Guest workers present (thousands) | C11: =INDEX(Labour!$L$6:$L$92,MATCH(C$7,Labour!$A$6:$A$92,0))/1000 -> 0 | D11: =INDEX(Labour!$L$6:$L$92,MATCH(D$7,Labour!$A$6:$A$92,0))/1000 -> 0 | E11: =INDEX(Labour!$L$6:$L$92,MATCH(E$7,Labour!$A$6:$A$92,0))/1000 -> 0 | F11: =INDEX(Labour!$L$6:$L$92,MATCH(F$7,Labour!$A$6:$A$92,0))/1000 -> 251.60759 | G11: =INDEX(Labour!$L$6:$L$92,MATCH(G$7,Labour!$A$6:$A$92,0))/1000 -> 477.17542 | H11: =INDEX(Labour!$L$6:$L$92,MATCH(H$7,Labour!$A$6:$A$92,0))/1000 -> 695.21043 | I11: =INDEX(Labour!$L$6:$L$92,MATCH(I$7,Labour!$A$6:$A$92,0))/1000 -> 912.4506 | J11: =INDEX(Labour!$L$6:$L$92,MATCH(J$7,Labour!$A$6:$A$92,0))/1000 -> 892.35618 | ... L11: =INDEX(Labour!$L$6:$L$92,MATCH(L$7,Labour!$A$6:$A$92,0))/1000 -> 1010.6804
B12: Core GDP ($bn) | C12: =INDEX(Economy!$O$6:$O$92,MATCH(C$7,Economy!$A$6:$A$92,0))/1000 -> 0.089459911 | D12: =INDEX(Economy!$O$6:$O$92,MATCH(D$7,Economy!$A$6:$A$92,0))/1000 -> 0.53072279 | E12: =INDEX(Economy!$O$6:$O$92,MATCH(E$7,Economy!$A$6:$A$92,0))/1000 -> 1.4038748 | F12: =INDEX(Economy!$O$6:$O$92,MATCH(F$7,Economy!$A$6:$A$92,0))/1000 -> 3.4856786 | G12: =INDEX(Economy!$O$6:$O$92,MATCH(G$7,Economy!$A$6:$A$92,0))/1000 -> 8.4921785 | H12: =INDEX(Economy!$O$6:$O$92,MATCH(H$7,Economy!$A$6:$A$92,0))/1000 -> 17.784832 | I12: =INDEX(Economy!$O$6:$O$92,MATCH(I$7,Economy!$A$6:$A$92,0))/1000 -> 38.05454 | J12: =INDEX(Economy!$O$6:$O$92,MATCH(J$7,Economy!$A$6:$A$92,0))/1000 -> 43.385375 | ... L12: =INDEX(Economy!$O$6:$O$92,MATCH(L$7,Economy!$A$6:$A$92,0))/1000 -> 54.846119
B13: GDP per resident vs the US | C13: =INDEX(Economy!$R$6:$R$92,MATCH(C$7,Economy!$A$6:$A$92,0)) -> 2.7066951 | D13: =INDEX(Economy!$R$6:$R$92,MATCH(D$7,Economy!$A$6:$A$92,0)) -> 1.9047716 | E13: =INDEX(Economy!$R$6:$R$92,MATCH(E$7,Economy!$A$6:$A$92,0)) -> 1.5841317 | F13: =INDEX(Economy!$R$6:$R$92,MATCH(F$7,Economy!$A$6:$A$92,0)) -> 2.0732207 | G13: =INDEX(Economy!$R$6:$R$92,MATCH(G$7,Economy!$A$6:$A$92,0)) -> 2.195255 | H13: =INDEX(Economy!$R$6:$R$92,MATCH(H$7,Economy!$A$6:$A$92,0)) -> 2.2644002 | I13: =INDEX(Economy!$R$6:$R$92,MATCH(I$7,Economy!$A$6:$A$92,0)) -> 2.1970691 | J13: =INDEX(Economy!$R$6:$R$92,MATCH(J$7,Economy!$A$6:$A$92,0)) -> 2.3779239 | ... L13: =INDEX(Economy!$R$6:$R$92,MATCH(L$7,Economy!$A$6:$A$92,0)) -> 3.1374743
B14: Development Fund investment ($m) | C14: =INDEX('Debt & cash'!$N$6:$N$92,MATCH(C$7,'Debt & cash'!$A$6:$A$92,0)) -> 0 | D14: =INDEX('Debt & cash'!$N$6:$N$92,MATCH(D$7,'Debt & cash'!$A$6:$A$92,0)) -> 0 | E14: =INDEX('Debt & cash'!$N$6:$N$92,MATCH(E$7,'Debt & cash'!$A$6:$A$92,0)) -> 446.02902 | F14: =INDEX('Debt & cash'!$N$6:$N$92,MATCH(F$7,'Debt & cash'!$A$6:$A$92,0)) -> 20.817736 | G14: =INDEX('Debt & cash'!$N$6:$N$92,MATCH(G$7,'Debt & cash'!$A$6:$A$92,0)) -> 183.68426 | H14: =INDEX('Debt & cash'!$N$6:$N$92,MATCH(H$7,'Debt & cash'!$A$6:$A$92,0)) -> 376.91517 | I14: =INDEX('Debt & cash'!$N$6:$N$92,MATCH(I$7,'Debt & cash'!$A$6:$A$92,0)) -> 721.07514 | J14: =INDEX('Debt & cash'!$N$6:$N$92,MATCH(J$7,'Debt & cash'!$A$6:$A$92,0)) -> 787.44796 | ... L14: =INDEX('Debt & cash'!$N$6:$N$92,MATCH(L$7,'Debt & cash'!$A$6:$A$92,0)) -> 218.61235
B15: Oil output (m barrels) | C15: =INDEX(Resources!$K$6:$K$92,MATCH(C$7,Resources!$A$6:$A$92,0)) -> 0 | D15: =INDEX(Resources!$K$6:$K$92,MATCH(D$7,Resources!$A$6:$A$92,0)) -> 0 | E15: =INDEX(Resources!$K$6:$K$92,MATCH(E$7,Resources!$A$6:$A$92,0)) -> 0.05 | F15: =INDEX(Resources!$K$6:$K$92,MATCH(F$7,Resources!$A$6:$A$92,0)) -> 10 | G15: =INDEX(Resources!$K$6:$K$92,MATCH(G$7,Resources!$A$6:$A$92,0)) -> 50 | H15: =INDEX(Resources!$K$6:$K$92,MATCH(H$7,Resources!$A$6:$A$92,0)) -> 100 | I15: =INDEX(Resources!$K$6:$K$92,MATCH(I$7,Resources!$A$6:$A$92,0)) -> 105 | J15: =INDEX(Resources!$K$6:$K$92,MATCH(J$7,Resources!$A$6:$A$92,0)) -> 150 | ... L15: =INDEX(Resources!$K$6:$K$92,MATCH(L$7,Resources!$A$6:$A$92,0)) -> 153
B16: National champions at home ($m) | C16: =INDEX(Champions!$AP$6:$AP$92,MATCH(C$7,Champions!$A$6:$A$92,0)) -> 0 | D16: =INDEX(Champions!$AP$6:$AP$92,MATCH(D$7,Champions!$A$6:$A$92,0)) -> 2.1188156 | E16: =INDEX(Champions!$AP$6:$AP$92,MATCH(E$7,Champions!$A$6:$A$92,0)) -> 25.726157 | F16: =INDEX(Champions!$AP$6:$AP$92,MATCH(F$7,Champions!$A$6:$A$92,0)) -> 134.12356 | G16: =INDEX(Champions!$AP$6:$AP$92,MATCH(G$7,Champions!$A$6:$A$92,0)) -> 372.65973 | H16: =INDEX(Champions!$AP$6:$AP$92,MATCH(H$7,Champions!$A$6:$A$92,0)) -> 751.60124 | I16: =INDEX(Champions!$AP$6:$AP$92,MATCH(I$7,Champions!$A$6:$A$92,0)) -> 1820.283 | J16: =INDEX(Champions!$AP$6:$AP$92,MATCH(J$7,Champions!$A$6:$A$92,0)) -> 2169.6299 | ... L16: =INDEX(Champions!$AP$6:$AP$92,MATCH(L$7,Champions!$A$6:$A$92,0)) -> 2580.9661
B17: Champions' assets abroad ($m) | C17: =INDEX(Champions!$AY$6:$AY$92,MATCH(C$7,Champions!$A$6:$A$92,0)) -> 0 | D17: =INDEX(Champions!$AY$6:$AY$92,MATCH(D$7,Champions!$A$6:$A$92,0)) -> 0 | E17: =INDEX(Champions!$AY$6:$AY$92,MATCH(E$7,Champions!$A$6:$A$92,0)) -> 52.121125 | F17: =INDEX(Champions!$AY$6:$AY$92,MATCH(F$7,Champions!$A$6:$A$92,0)) -> 348.39172 | G17: =INDEX(Champions!$AY$6:$AY$92,MATCH(G$7,Champions!$A$6:$A$92,0)) -> 1850.0567 | H17: =INDEX(Champions!$AY$6:$AY$92,MATCH(H$7,Champions!$A$6:$A$92,0)) -> 3158.3206 | I17: =INDEX(Champions!$AY$6:$AY$92,MATCH(I$7,Champions!$A$6:$A$92,0)) -> 4601.5182 | J17: =INDEX(Champions!$AY$6:$AY$92,MATCH(J$7,Champions!$A$6:$A$92,0)) -> 6566.4413 | ... L17: =INDEX(Champions!$AY$6:$AY$92,MATCH(L$7,Champions!$A$6:$A$92,0)) -> 9716.7072
B18: Patents per resident vs the US | C18: =INDEX(Champions!$I$6:$I$92,MATCH(C$7,Champions!$A$6:$A$92,0)) -> 0 | D18: =INDEX(Champions!$I$6:$I$92,MATCH(D$7,Champions!$A$6:$A$92,0)) -> 0.29500056 | E18: =INDEX(Champions!$I$6:$I$92,MATCH(E$7,Champions!$A$6:$A$92,0)) -> 1.0490154 | F18: =INDEX(Champions!$I$6:$I$92,MATCH(F$7,Champions!$A$6:$A$92,0)) -> 1.4538065 | G18: =INDEX(Champions!$I$6:$I$92,MATCH(G$7,Champions!$A$6:$A$92,0)) -> 1.7892297 | H18: =INDEX(Champions!$I$6:$I$92,MATCH(H$7,Champions!$A$6:$A$92,0)) -> 1.6276533 | I18: =INDEX(Champions!$I$6:$I$92,MATCH(I$7,Champions!$A$6:$A$92,0)) -> 1.6302071 | J18: =INDEX(Champions!$I$6:$I$92,MATCH(J$7,Champions!$A$6:$A$92,0)) -> 1.6642104 | ... L18: =INDEX(Champions!$I$6:$I$92,MATCH(L$7,Champions!$A$6:$A$92,0)) -> 1.2513167
B19: Extra arrivals drawn by the lead | C19: =INDEX(Labour!$AL$6:$AL$92,MATCH(C$7,Labour!$A$6:$A$92,0)) -> 0 | D19: =INDEX(Labour!$AL$6:$AL$92,MATCH(D$7,Labour!$A$6:$A$92,0)) -> 10729.839 | E19: =INDEX(Labour!$AL$6:$AL$92,MATCH(E$7,Labour!$A$6:$A$92,0)) -> 33751.353 | F19: =INDEX(Labour!$AL$6:$AL$92,MATCH(F$7,Labour!$A$6:$A$92,0)) -> 128663.33 | G19: =INDEX(Labour!$AL$6:$AL$92,MATCH(G$7,Labour!$A$6:$A$92,0)) -> 311422.17 | H19: =INDEX(Labour!$AL$6:$AL$92,MATCH(H$7,Labour!$A$6:$A$92,0)) -> 332155.67 | I19: =INDEX(Labour!$AL$6:$AL$92,MATCH(I$7,Labour!$A$6:$A$92,0)) -> 165282.01 | J19: =INDEX(Labour!$AL$6:$AL$92,MATCH(J$7,Labour!$A$6:$A$92,0)) -> 328439.07 | ... L19: =INDEX(Labour!$AL$6:$AL$92,MATCH(L$7,Labour!$A$6:$A$92,0)) -> 304486.38
B20: Champion-related jobs / labour force | C20: =INDEX(Labour!$G$6:$G$92,MATCH(C$7,Labour!$A$6:$A$92,0)) -> 0 | D20: =INDEX(Labour!$G$6:$G$92,MATCH(D$7,Labour!$A$6:$A$92,0)) -> 0.0037705251 | E20: =INDEX(Labour!$G$6:$G$92,MATCH(E$7,Labour!$A$6:$A$92,0)) -> 0.017307046 | F20: =INDEX(Labour!$G$6:$G$92,MATCH(F$7,Labour!$A$6:$A$92,0)) -> 0.039010417 | G20: =INDEX(Labour!$G$6:$G$92,MATCH(G$7,Labour!$A$6:$A$92,0)) -> 0.045105629 | H20: =INDEX(Labour!$G$6:$G$92,MATCH(H$7,Labour!$A$6:$A$92,0)) -> 0.043428298 | I20: =INDEX(Labour!$G$6:$G$92,MATCH(I$7,Labour!$A$6:$A$92,0)) -> 0.049527061 | J20: =INDEX(Labour!$G$6:$G$92,MATCH(J$7,Labour!$A$6:$A$92,0)) -> 0.051098745 | ... L20: =INDEX(Labour!$G$6:$G$92,MATCH(L$7,Labour!$A$6:$A$92,0)) -> 0.047438561
B21: Union output lost to Pacifica | C21: =INDEX(Labour!$BL$6:$BL$92,MATCH(C$7,Labour!$A$6:$A$92,0)) -> 0.000239162 | D21: =INDEX(Labour!$BL$6:$BL$92,MATCH(D$7,Labour!$A$6:$A$92,0)) -> 0.012776027 | E21: =INDEX(Labour!$BL$6:$BL$92,MATCH(E$7,Labour!$A$6:$A$92,0)) -> 0.041271792 | F21: =INDEX(Labour!$BL$6:$BL$92,MATCH(F$7,Labour!$A$6:$A$92,0)) -> 0.086575049 | G21: =INDEX(Labour!$BL$6:$BL$92,MATCH(G$7,Labour!$A$6:$A$92,0)) -> 0.13733836 | H21: =INDEX(Labour!$BL$6:$BL$92,MATCH(H$7,Labour!$A$6:$A$92,0)) -> 0.17093966 | I21: =INDEX(Labour!$BL$6:$BL$92,MATCH(I$7,Labour!$A$6:$A$92,0)) -> 0.19017257 | J21: =INDEX(Labour!$BL$6:$BL$92,MATCH(J$7,Labour!$A$6:$A$92,0)) -> 0.20659515 | ... L21: =INDEX(Labour!$BL$6:$BL$92,MATCH(L$7,Labour!$A$6:$A$92,0)) -> 0.31652374
B22: Union population (m) | C22: =INDEX(Labour!$AX$6:$AX$92,MATCH(C$7,Labour!$A$6:$A$92,0)) -> 16.87 | D22: =INDEX(Labour!$AX$6:$AX$92,MATCH(D$7,Labour!$A$6:$A$92,0)) -> 24.933288 | E22: =INDEX(Labour!$AX$6:$AX$92,MATCH(E$7,Labour!$A$6:$A$92,0)) -> 39.727081 | F22: =INDEX(Labour!$AX$6:$AX$92,MATCH(F$7,Labour!$A$6:$A$92,0)) -> 53.621174 | G22: =INDEX(Labour!$AX$6:$AX$92,MATCH(G$7,Labour!$A$6:$A$92,0)) -> 63.281477 | H22: =INDEX(Labour!$AX$6:$AX$92,MATCH(H$7,Labour!$A$6:$A$92,0)) -> 71.893629 | I22: =INDEX(Labour!$AX$6:$AX$92,MATCH(I$7,Labour!$A$6:$A$92,0)) -> 75.401657 | J22: =INDEX(Labour!$AX$6:$AX$92,MATCH(J$7,Labour!$A$6:$A$92,0)) -> 78.407832 | ... L22: =INDEX(Labour!$AX$6:$AX$92,MATCH(L$7,Labour!$A$6:$A$92,0)) -> 85.850319
B23: Income from abroad ($m) | C23: =INDEX(Abroad!$M$6:$M$92,MATCH(C$7,Abroad!$A$6:$A$92,0)) -> 0.016660753 | D23: =INDEX(Abroad!$M$6:$M$92,MATCH(D$7,Abroad!$A$6:$A$92,0)) -> 0.38852724 | E23: =INDEX(Abroad!$M$6:$M$92,MATCH(E$7,Abroad!$A$6:$A$92,0)) -> 7.7105338 | F23: =INDEX(Abroad!$M$6:$M$92,MATCH(F$7,Abroad!$A$6:$A$92,0)) -> 39.600522 | G23: =INDEX(Abroad!$M$6:$M$92,MATCH(G$7,Abroad!$A$6:$A$92,0)) -> 203.38308 | H23: =INDEX(Abroad!$M$6:$M$92,MATCH(H$7,Abroad!$A$6:$A$92,0)) -> 401.58639 | I23: =INDEX(Abroad!$M$6:$M$92,MATCH(I$7,Abroad!$A$6:$A$92,0)) -> 733.46391 | J23: =INDEX(Abroad!$M$6:$M$92,MATCH(J$7,Abroad!$A$6:$A$92,0)) -> 1234.8877 | ... L23: =INDEX(Abroad!$M$6:$M$92,MATCH(L$7,Abroad!$A$6:$A$92,0)) -> 1499.7244
B24: National income ($bn) | C24: =INDEX(Abroad!$P$6:$P$92,MATCH(C$7,Abroad!$A$6:$A$92,0))/1000 -> 0.089476572 | D24: =INDEX(Abroad!$P$6:$P$92,MATCH(D$7,Abroad!$A$6:$A$92,0))/1000 -> 0.53111132 | E24: =INDEX(Abroad!$P$6:$P$92,MATCH(E$7,Abroad!$A$6:$A$92,0))/1000 -> 1.410797 | F24: =INDEX(Abroad!$P$6:$P$92,MATCH(F$7,Abroad!$A$6:$A$92,0))/1000 -> 3.4924339 | G24: =INDEX(Abroad!$P$6:$P$92,MATCH(G$7,Abroad!$A$6:$A$92,0))/1000 -> 8.5629107 | H24: =INDEX(Abroad!$P$6:$P$92,MATCH(H$7,Abroad!$A$6:$A$92,0))/1000 -> 17.952344 | I24: =INDEX(Abroad!$P$6:$P$92,MATCH(I$7,Abroad!$A$6:$A$92,0))/1000 -> 38.344649 | J24: =INDEX(Abroad!$P$6:$P$92,MATCH(J$7,Abroad!$A$6:$A$92,0))/1000 -> 44.142542 | ... L24: =INDEX(Abroad!$P$6:$P$92,MATCH(L$7,Abroad!$A$6:$A$92,0))/1000 -> 55.773407
B25: Treasury
B26: Receipts ($m) | C26: =INDEX(Budget!$M$6:$M$92,MATCH(C$7,Budget!$A$6:$A$92,0)) -> 7.7742456 | D26: =INDEX(Budget!$M$6:$M$92,MATCH(D$7,Budget!$A$6:$A$92,0)) -> 68.560763 | E26: =INDEX(Budget!$M$6:$M$92,MATCH(E$7,Budget!$A$6:$A$92,0)) -> 187.92018 | F26: =INDEX(Budget!$M$6:$M$92,MATCH(F$7,Budget!$A$6:$A$92,0)) -> 380.65575 | G26: =INDEX(Budget!$M$6:$M$92,MATCH(G$7,Budget!$A$6:$A$92,0)) -> 857.87667 | H26: =INDEX(Budget!$M$6:$M$92,MATCH(H$7,Budget!$A$6:$A$92,0)) -> 1753.8047 | I26: =INDEX(Budget!$M$6:$M$92,MATCH(I$7,Budget!$A$6:$A$92,0)) -> 4435.0423 | J26: =INDEX(Budget!$M$6:$M$92,MATCH(J$7,Budget!$A$6:$A$92,0)) -> 4544.4058 | ... L26: =INDEX(Budget!$M$6:$M$92,MATCH(L$7,Budget!$A$6:$A$92,0)) -> 5330.0415
B27: Crown share dividends ($m) | C27: =INDEX(Budget!$K$6:$K$92,MATCH(C$7,Budget!$A$6:$A$92,0)) -> 0 | D27: =INDEX(Budget!$K$6:$K$92,MATCH(D$7,Budget!$A$6:$A$92,0)) -> 0 | E27: =INDEX(Budget!$K$6:$K$92,MATCH(E$7,Budget!$A$6:$A$92,0)) -> 0.97533384 | F27: =INDEX(Budget!$K$6:$K$92,MATCH(F$7,Budget!$A$6:$A$92,0)) -> 5.2882159 | G27: =INDEX(Budget!$K$6:$K$92,MATCH(G$7,Budget!$A$6:$A$92,0)) -> 18.682667 | H27: =INDEX(Budget!$K$6:$K$92,MATCH(H$7,Budget!$A$6:$A$92,0)) -> 35.727657 | I27: =INDEX(Budget!$K$6:$K$92,MATCH(I$7,Budget!$A$6:$A$92,0)) -> 67.896409 | J27: =INDEX(Budget!$K$6:$K$92,MATCH(J$7,Budget!$A$6:$A$92,0)) -> 95.257938 | ... L27: =INDEX(Budget!$K$6:$K$92,MATCH(L$7,Budget!$A$6:$A$92,0)) -> 104.66775
B28: Guest-worker levy ($m) | C28: =INDEX(Budget!$J$6:$J$92,MATCH(C$7,Budget!$A$6:$A$92,0)) -> 0 | D28: =INDEX(Budget!$J$6:$J$92,MATCH(D$7,Budget!$A$6:$A$92,0)) -> 0 | E28: =INDEX(Budget!$J$6:$J$92,MATCH(E$7,Budget!$A$6:$A$92,0)) -> 0 | F28: =INDEX(Budget!$J$6:$J$92,MATCH(F$7,Budget!$A$6:$A$92,0)) -> 22.903459 | G28: =INDEX(Budget!$J$6:$J$92,MATCH(G$7,Budget!$A$6:$A$92,0)) -> 66.323025 | H28: =INDEX(Budget!$J$6:$J$92,MATCH(H$7,Budget!$A$6:$A$92,0)) -> 139.32065 | I28: =INDEX(Budget!$J$6:$J$92,MATCH(I$7,Budget!$A$6:$A$92,0)) -> 323.38067 | J28: =INDEX(Budget!$J$6:$J$92,MATCH(J$7,Budget!$A$6:$A$92,0)) -> 316.79547 | ... L28: =INDEX(Budget!$J$6:$J$92,MATCH(L$7,Budget!$A$6:$A$92,0)) -> 334.03131
B29: Spending ($m) | C29: =INDEX(Budget!$Y$6:$Y$92,MATCH(C$7,Budget!$A$6:$A$92,0)) -> 7.515048 | D29: =INDEX(Budget!$Y$6:$Y$92,MATCH(D$7,Budget!$A$6:$A$92,0)) -> 58.074635 | E29: =INDEX(Budget!$Y$6:$Y$92,MATCH(E$7,Budget!$A$6:$A$92,0)) -> 119.94803 | F29: =INDEX(Budget!$Y$6:$Y$92,MATCH(F$7,Budget!$A$6:$A$92,0)) -> 292.62049 | G29: =INDEX(Budget!$Y$6:$Y$92,MATCH(G$7,Budget!$A$6:$A$92,0)) -> 656.90278 | H29: =INDEX(Budget!$Y$6:$Y$92,MATCH(H$7,Budget!$A$6:$A$92,0)) -> 1398.709 | I29: =INDEX(Budget!$Y$6:$Y$92,MATCH(I$7,Budget!$A$6:$A$92,0)) -> 3294.7738 | J29: =INDEX(Budget!$Y$6:$Y$92,MATCH(J$7,Budget!$A$6:$A$92,0)) -> 3507.0311 | ... L29: =INDEX(Budget!$Y$6:$Y$92,MATCH(L$7,Budget!$A$6:$A$92,0)) -> 5001.3762
B30: Defence & overseas / GDP | C30: =INDEX(Budget!$AC$6:$AC$92,MATCH(C$7,Budget!$A$6:$A$92,0)) -> 0.013648572 | D30: =INDEX(Budget!$AC$6:$AC$92,MATCH(D$7,Budget!$A$6:$A$92,0)) -> 0.050429886 | E30: =INDEX(Budget!$AC$6:$AC$92,MATCH(E$7,Budget!$A$6:$A$92,0)) -> 0.014531666 | F30: =INDEX(Budget!$AC$6:$AC$92,MATCH(F$7,Budget!$A$6:$A$92,0)) -> 0.0069343391 | G30: =INDEX(Budget!$AC$6:$AC$92,MATCH(G$7,Budget!$A$6:$A$92,0)) -> 0.0061317934 | H30: =INDEX(Budget!$AC$6:$AC$92,MATCH(H$7,Budget!$A$6:$A$92,0)) -> 0.0057507348 | I30: =INDEX(Budget!$AC$6:$AC$92,MATCH(I$7,Budget!$A$6:$A$92,0)) -> 0.011053752 | J30: =INDEX(Budget!$AC$6:$AC$92,MATCH(J$7,Budget!$A$6:$A$92,0)) -> 0.0055404538 | ... L30: =INDEX(Budget!$AC$6:$AC$92,MATCH(L$7,Budget!$A$6:$A$92,0)) -> 0.0039313037
B31: Public debt ($m) | C31: =INDEX('Debt & cash'!$R$6:$R$92,MATCH(C$7,'Debt & cash'!$A$6:$A$92,0)) -> 17.018376 | D31: =INDEX('Debt & cash'!$R$6:$R$92,MATCH(D$7,'Debt & cash'!$A$6:$A$92,0)) -> 13.277584 | E31: =INDEX('Debt & cash'!$R$6:$R$92,MATCH(E$7,'Debt & cash'!$A$6:$A$92,0)) -> 0 | F31: =INDEX('Debt & cash'!$R$6:$R$92,MATCH(F$7,'Debt & cash'!$A$6:$A$92,0)) -> 174.28393 | G31: =INDEX('Debt & cash'!$R$6:$R$92,MATCH(G$7,'Debt & cash'!$A$6:$A$92,0)) -> 424.60892 | H31: =INDEX('Debt & cash'!$R$6:$R$92,MATCH(H$7,'Debt & cash'!$A$6:$A$92,0)) -> 889.24158 | I31: =INDEX('Debt & cash'!$R$6:$R$92,MATCH(I$7,'Debt & cash'!$A$6:$A$92,0)) -> 1902.727 | J31: =INDEX('Debt & cash'!$R$6:$R$92,MATCH(J$7,'Debt & cash'!$A$6:$A$92,0)) -> 2169.2688 | ... L31: =INDEX('Debt & cash'!$R$6:$R$92,MATCH(L$7,'Debt & cash'!$A$6:$A$92,0)) -> 2920.4904
B32: Debt / GDP | C32: =INDEX('Debt & cash'!$V$6:$V$92,MATCH(C$7,'Debt & cash'!$A$6:$A$92,0)) -> 0.19023467 | D32: =INDEX('Debt & cash'!$V$6:$V$92,MATCH(D$7,'Debt & cash'!$A$6:$A$92,0)) -> 0.025017926 | E32: =INDEX('Debt & cash'!$V$6:$V$92,MATCH(E$7,'Debt & cash'!$A$6:$A$92,0)) -> 0 | F32: =INDEX('Debt & cash'!$V$6:$V$92,MATCH(F$7,'Debt & cash'!$A$6:$A$92,0)) -> 0.05 | G32: =INDEX('Debt & cash'!$V$6:$V$92,MATCH(G$7,'Debt & cash'!$A$6:$A$92,0)) -> 0.05 | H32: =INDEX('Debt & cash'!$V$6:$V$92,MATCH(H$7,'Debt & cash'!$A$6:$A$92,0)) -> 0.05 | I32: =INDEX('Debt & cash'!$V$6:$V$92,MATCH(I$7,'Debt & cash'!$A$6:$A$92,0)) -> 0.05 | J32: =INDEX('Debt & cash'!$V$6:$V$92,MATCH(J$7,'Debt & cash'!$A$6:$A$92,0)) -> 0.05 | ... L32: =INDEX('Debt & cash'!$V$6:$V$92,MATCH(L$7,'Debt & cash'!$A$6:$A$92,0)) -> 0.053248808
B33: Treasury Reserve Fund ($m) | C33: =INDEX('Debt & cash'!$S$6:$S$92,MATCH(C$7,'Debt & cash'!$A$6:$A$92,0)) -> 0 | D33: =INDEX('Debt & cash'!$S$6:$S$92,MATCH(D$7,'Debt & cash'!$A$6:$A$92,0)) -> 1.7243131 | E33: =INDEX('Debt & cash'!$S$6:$S$92,MATCH(E$7,'Debt & cash'!$A$6:$A$92,0)) -> 62.025853 | F33: =INDEX('Debt & cash'!$S$6:$S$92,MATCH(F$7,'Debt & cash'!$A$6:$A$92,0)) -> 87.864949 | G33: =INDEX('Debt & cash'!$S$6:$S$92,MATCH(G$7,'Debt & cash'!$A$6:$A$92,0)) -> 148.03386 | H33: =INDEX('Debt & cash'!$S$6:$S$92,MATCH(H$7,'Debt & cash'!$A$6:$A$92,0)) -> 267.52047 | I33: =INDEX('Debt & cash'!$S$6:$S$92,MATCH(I$7,'Debt & cash'!$A$6:$A$92,0)) -> 361.88634 | J33: =INDEX('Debt & cash'!$S$6:$S$92,MATCH(J$7,'Debt & cash'!$A$6:$A$92,0)) -> 610.82105 | ... L33: =INDEX('Debt & cash'!$S$6:$S$92,MATCH(L$7,'Debt & cash'!$A$6:$A$92,0)) -> 1344.0797
B34: Loans abroad outstanding ($m) | C34: =INDEX(Loans!$X$6:$X$92,MATCH(C$7,Loans!$A$6:$A$92,0)) -> 0 | D34: =INDEX(Loans!$X$6:$X$92,MATCH(D$7,Loans!$A$6:$A$92,0)) -> 0 | E34: =INDEX(Loans!$X$6:$X$92,MATCH(E$7,Loans!$A$6:$A$92,0)) -> 29.765514 | F34: =INDEX(Loans!$X$6:$X$92,MATCH(F$7,Loans!$A$6:$A$92,0)) -> 113.35301 | G34: =INDEX(Loans!$X$6:$X$92,MATCH(G$7,Loans!$A$6:$A$92,0)) -> 189.84116 | H34: =INDEX(Loans!$X$6:$X$92,MATCH(H$7,Loans!$A$6:$A$92,0)) -> 137.06972 | I34: =INDEX(Loans!$X$6:$X$92,MATCH(I$7,Loans!$A$6:$A$92,0)) -> 1654.8606 | J34: =INDEX(Loans!$X$6:$X$92,MATCH(J$7,Loans!$A$6:$A$92,0)) -> 2380.0908 | ... L34: =INDEX(Loans!$X$6:$X$92,MATCH(L$7,Loans!$A$6:$A$92,0)) -> 2651.9826
B35: Monetary gold ($m) | C35: =INDEX('Gold & money'!$F$6:$F$92,MATCH(C$7,'Gold & money'!$A$6:$A$92,0)) -> 18.37892 | D35: =INDEX('Gold & money'!$F$6:$F$92,MATCH(D$7,'Gold & money'!$A$6:$A$92,0)) -> 190.37822 | E35: =INDEX('Gold & money'!$F$6:$F$92,MATCH(E$7,'Gold & money'!$A$6:$A$92,0)) -> 303.86467 | F35: =INDEX('Gold & money'!$F$6:$F$92,MATCH(F$7,'Gold & money'!$A$6:$A$92,0)) -> 389.62172 | G35: =INDEX('Gold & money'!$F$6:$F$92,MATCH(G$7,'Gold & money'!$A$6:$A$92,0)) -> 598.10071 | H35: =INDEX('Gold & money'!$F$6:$F$92,MATCH(H$7,'Gold & money'!$A$6:$A$92,0)) -> 951.94144 | I35: =INDEX('Gold & money'!$F$6:$F$92,MATCH(I$7,'Gold & money'!$A$6:$A$92,0)) -> 1299.5056 | J35: =INDEX('Gold & money'!$F$6:$F$92,MATCH(J$7,'Gold & money'!$A$6:$A$92,0)) -> 1707.6315 | ... L35: =INDEX('Gold & money'!$F$6:$F$92,MATCH(L$7,'Gold & money'!$A$6:$A$92,0)) -> 2363.0908
B36: Navy
B37: Pacifica's navy bill ($m) | C37: =INDEX(Navy!$Y$6:$Y$92,MATCH(C$7,Navy!$A$6:$A$92,0)) -> 0 | D37: =INDEX(Navy!$Y$6:$Y$92,MATCH(D$7,Navy!$A$6:$A$92,0)) -> 3.77429 | E37: =INDEX(Navy!$Y$6:$Y$92,MATCH(E$7,Navy!$A$6:$A$92,0)) -> 7.76064 | F37: =INDEX(Navy!$Y$6:$Y$92,MATCH(F$7,Navy!$A$6:$A$92,0)) -> 8.8141188 | G37: =INDEX(Navy!$Y$6:$Y$92,MATCH(G$7,Navy!$A$6:$A$92,0)) -> 28.711684 | H37: =INDEX(Navy!$Y$6:$Y$92,MATCH(H$7,Navy!$A$6:$A$92,0)) -> 74.37585 | I37: =INDEX(Navy!$Y$6:$Y$92,MATCH(I$7,Navy!$A$6:$A$92,0)) -> 152.38039 | J37: =INDEX(Navy!$Y$6:$Y$92,MATCH(J$7,Navy!$A$6:$A$92,0)) -> 145.28468 | ... L37: =INDEX(Navy!$Y$6:$Y$92,MATCH(L$7,Navy!$A$6:$A$92,0)) -> 163.22577
B38: Ships in service | C38: =INDEX(Navy!$K$6:$K$92,MATCH(C$7,Navy!$A$6:$A$92,0)) -> 0 | D38: =INDEX(Navy!$K$6:$K$92,MATCH(D$7,Navy!$A$6:$A$92,0)) -> 12 | E38: =INDEX(Navy!$K$6:$K$92,MATCH(E$7,Navy!$A$6:$A$92,0)) -> 25 | F38: =INDEX(Navy!$K$6:$K$92,MATCH(F$7,Navy!$A$6:$A$92,0)) -> 49 | G38: =INDEX(Navy!$K$6:$K$92,MATCH(G$7,Navy!$A$6:$A$92,0)) -> 68 | H38: =INDEX(Navy!$K$6:$K$92,MATCH(H$7,Navy!$A$6:$A$92,0)) -> 115 | I38: =INDEX(Navy!$K$6:$K$92,MATCH(I$7,Navy!$A$6:$A$92,0)) -> 183 | J38: =INDEX(Navy!$K$6:$K$92,MATCH(J$7,Navy!$A$6:$A$92,0)) -> 180 | ... L38: =INDEX(Navy!$K$6:$K$92,MATCH(L$7,Navy!$A$6:$A$92,0)) -> 162
B39: Capital ships: Pacifica | C39: =INDEX(Navy!$AA$6:$AA$92,MATCH(C$7,Navy!$A$6:$A$92,0)) -> 0 | D39: =INDEX(Navy!$AA$6:$AA$92,MATCH(D$7,Navy!$A$6:$A$92,0)) -> 0 | E39: =INDEX(Navy!$AA$6:$AA$92,MATCH(E$7,Navy!$A$6:$A$92,0)) -> 0 | F39: =INDEX(Navy!$AA$6:$AA$92,MATCH(F$7,Navy!$A$6:$A$92,0)) -> 0 | G39: =INDEX(Navy!$AA$6:$AA$92,MATCH(G$7,Navy!$A$6:$A$92,0)) -> 2 | H39: =INDEX(Navy!$AA$6:$AA$92,MATCH(H$7,Navy!$A$6:$A$92,0)) -> 9 | I39: =INDEX(Navy!$AA$6:$AA$92,MATCH(I$7,Navy!$A$6:$A$92,0)) -> 14 | J39: =INDEX(Navy!$AA$6:$AA$92,MATCH(J$7,Navy!$A$6:$A$92,0)) -> 14 | ... L39: =INDEX(Navy!$AA$6:$AA$92,MATCH(L$7,Navy!$A$6:$A$92,0)) -> 14
B40: Capital ships: Pacifica + Japan / Britain | C40: =INDEX(Navy!$AE$6:$AE$92,MATCH(C$7,Navy!$A$6:$A$92,0)) -> 0 | D40: =INDEX(Navy!$AE$6:$AE$92,MATCH(D$7,Navy!$A$6:$A$92,0)) -> 0 | E40: =INDEX(Navy!$AE$6:$AE$92,MATCH(E$7,Navy!$A$6:$A$92,0)) -> 0 | F40: =INDEX(Navy!$AE$6:$AE$92,MATCH(F$7,Navy!$A$6:$A$92,0)) -> 0 | G40: =INDEX(Navy!$AE$6:$AE$92,MATCH(G$7,Navy!$A$6:$A$92,0)) -> 0 | H40: =INDEX(Navy!$AE$6:$AE$92,MATCH(H$7,Navy!$A$6:$A$92,0)) -> 0.59090909 | I40: =INDEX(Navy!$AE$6:$AE$92,MATCH(I$7,Navy!$A$6:$A$92,0)) -> 0.52380952 | J40: =INDEX(Navy!$AE$6:$AE$92,MATCH(J$7,Navy!$A$6:$A$92,0)) -> 1 | ... L40: =INDEX(Navy!$AE$6:$AE$92,MATCH(L$7,Navy!$A$6:$A$92,0)) -> 1
B41: Sailors saved by oil firing | C41: =INDEX(Navy!$O$6:$O$92,MATCH(C$7,Navy!$A$6:$A$92,0)) -> 0 | D41: =INDEX(Navy!$O$6:$O$92,MATCH(D$7,Navy!$A$6:$A$92,0)) -> 0 | E41: =INDEX(Navy!$O$6:$O$92,MATCH(E$7,Navy!$A$6:$A$92,0)) -> 0 | F41: =INDEX(Navy!$O$6:$O$92,MATCH(F$7,Navy!$A$6:$A$92,0)) -> 747.4359 | G41: =INDEX(Navy!$O$6:$O$92,MATCH(G$7,Navy!$A$6:$A$92,0)) -> 3111.0256 | H41: =INDEX(Navy!$O$6:$O$92,MATCH(H$7,Navy!$A$6:$A$92,0)) -> 6611.2821 | I41: =INDEX(Navy!$O$6:$O$92,MATCH(I$7,Navy!$A$6:$A$92,0)) -> 9632.0513 | J41: =INDEX(Navy!$O$6:$O$92,MATCH(J$7,Navy!$A$6:$A$92,0)) -> 9691.2821 | ... L41: =INDEX(Navy!$O$6:$O$92,MATCH(L$7,Navy!$A$6:$A$92,0)) -> 10438.718
B42: Japan
...

Sheet Changes
A1: What changed from Sol's model
A2: Sol's CR-018/CR-019 workbook (working case) against this model, with the reason for each difference.
A3: Sol's values are typed in from Pacifica_CR018_CR019_financial_model_1846-1932.xlsx; this model's values are live.
B5: Measure | C5: Year | D5: Sol's model | E5: This model | F5: Ratio | G5: Why it differs
B6: Core residents (m) | C6: 1895 | D6: 6.01 | E6: =INDEX(People!$L$6:$L$92,MATCH(C6,People!$A$6:$A$92,0))/1000000 -> 8.3296699 | F6: =IF(D6<>0,E6/D6,0) -> 1.3859684 | G6: Similar until 1895.
B7: Core residents (m) | C7: 1913 | D7: 9.44 | E7: =INDEX(People!$L$6:$L$92,MATCH(C7,People!$A$6:$A$92,0))/1000000 -> 19.227664 | F7: =IF(D7<>0,E7/D7,0) -> 2.0368288 | G7: No exclusion act, family programmes and skilled entry keep migration higher after 1888.
B8: Core residents (m) | C8: 1929 | D8: 12.92 | E8: =INDEX(People!$L$6:$L$92,MATCH(C8,People!$A$6:$A$92,0))/1000000 -> 33.396639 | F8: =IF(D8<>0,E8/D8,0) -> 2.5848792 | G8: Baseline arrivals, plus people drawn by Pacifica's lead: skilled migrants and families (B10), settled guest workers (B11), and Europeans who would have gone to the Union (B12).
B9: Core GDP ($bn) | C9: 1895 | D9: 2.24 | E9: =INDEX(Economy!$O$6:$O$92,MATCH(C9,Economy!$A$6:$A$92,0))/1000 -> 3.4856786 | F9: =IF(D9<>0,E9/D9,0) -> 1.5561065 | G9: Sol's per-resident output was higher early, lower late.
B10: Core GDP ($bn) | C10: 1913 | D10: 5.62 | E10: =INDEX(Economy!$O$6:$O$92,MATCH(C10,Economy!$A$6:$A$92,0))/1000 -> 17.784832 | F10: =IF(D10<>0,E10/D10,0) -> 3.1645608
B11: Core GDP ($bn) | C11: 1929 | D11: 12.15 | E11: =INDEX(Economy!$O$6:$O$92,MATCH(C11,Economy!$A$6:$A$92,0))/1000 -> 69.472342 | F11: =IF(D11<>0,E11/D11,0) -> 5.7178882 | G11: Sol's 1929 economy was the historical American West (about 1.1x US output per person). This one is about 2x: the trend path near historical California, the national champions (B9), the extra talent (B10) and the Development Fund. Total GDP is also larger because there are more people.
B12: Core GDP ($bn) | C12: 1932 | D12: 7.11 | E12: =INDEX(Economy!$O$6:$O$92,MATCH(C12,Economy!$A$6:$A$92,0))/1000 -> 54.846119 | F12: =IF(D12<>0,E12/D12,0) -> 7.7139408 | G12: Sol's slump was -41% in money terms, worse than the Union's. Here about -24%: Pacifica keeps its market open, lends its gold and its central bank acts (§34, CR-020).
B13: Treasury receipts ($m) | C13: 1929 | D13: 1255 | E13: =INDEX(Budget!$M$6:$M$92,MATCH(C13,Budget!$A$6:$A$92,0)) -> 7577.4189 | F13: =IF(D13<>0,E13/D13,0) -> 6.037784
B14: Navy ($m) | C14: 1913 | D14: 114.5 | E14: =INDEX(Navy!$Y$6:$Y$92,MATCH(C14,Navy!$A$6:$A$92,0)) -> 74.37585 | F14: =IF(D14<>0,E14/D14,0) -> 0.64957074 | G14: Sol's navy kept 24 seagoing hulls fixed from 1905 and added a flat allowance. Here the fleet is built ship by ship.
B15: Navy ($m) | C15: 1929 | D15: 195 | E15: =INDEX(Navy!$Y$6:$Y$92,MATCH(C15,Navy!$A$6:$A$92,0)) -> 183.35254 | F15: =IF(D15<>0,E15/D15,0) -> 0.94026942 | G15: Includes Pacifica's 65% of the common navy from 1927.
B16: Public debt ($m) | C16: 1932 | D16: 119.8 | E16: =INDEX('Debt & cash'!$R$6:$R$92,MATCH(C16,'Debt & cash'!$A$6:$A$92,0)) -> 2920.4904 | F16: =IF(D16<>0,E16/D16,0) -> 24.37805 | G16: Here a standing debt of about 5% of GDP is kept for the Reserve Bank (OPEN-020-06), and the rescue is paid from the Reserve Fund.
B17: Treasury cash ($m) | C17: 1929 | D17: 2326.7 | E17: =INDEX('Debt & cash'!$M$6:$M$92,MATCH(C17,'Debt & cash'!$A$6:$A$92,0)) -> 1894.3547 | F17: =IF(D17<>0,E17/D17,0) -> 0.81418091 | G17: Sol's surpluses piled up as $2.3bn of idle cash. Here surpluses repay debt or go to the Reserve Fund.
B18: Monetary gold ($m) | C18: 1932 | D18: 1355.5 | E18: =INDEX('Gold & money'!$F$6:$F$92,MATCH(C18,'Gold & money'!$A$6:$A$92,0)) -> 2363.0908 | F18: =IF(D18<>0,E18/D18,0) -> 1.7433352
B20: Structural changes
B21: Fleet | C21: Nine ship classes with the canon technology dates: oil-fired torpedo boats in the 1880s, oil cruisers in the early 1890s, turbine destroyers 1893-95, turbine cruisers 1898, all-big-gun turbine capital ships from 1903 (proposed). HMS Dreadnought changes nothing for Pacifica's budget: there is no 1906 jump.
B22: Oil | C22: Sol's model counted oil inside 'other minerals' with no royalty and no navy effect. Here the state takes a 1/8 royalty, the navy burns its own oil, and the sheets show sailors and fuel saved by oil firing.
B23: Technology | C23: The approved oil (1876) and turbine (1885) programmes and the proposed electrical institute (1886) are costed Events, on top of a standing technical budget.
B24: Japan | C24: Japan has a conserved Treasury cash account. The 1927 panic combines bank losses, domestic withdrawals and a tested foreign-settlement shortage.
B25: Events | C25: One ledger lists every dated commitment with its canon status and section, so a story change is one row to edit.
B26: Canal | C26: Owned by the state, as the regency's achievement (Sol's model: 20% public). Tolls from 1901.
B27: World | C27: A new sheet sets Pacifica, Japan and the order against the Union, Britain and Germany.
B28: Layout | C28: Years run down the page; inputs, events and results are separate; every heading has a definition.
B29: CR-020 | C29: Income from private investment abroad (national income), named export sectors, the Gulf admission switch, Pacifica's milder price fall in 1930-32, an oil compact with the Gulf, a standing public debt for the Reserve Bank, the Thalassia and islands programme as Events, a drag on the Union's output, and a Development Fund that invests most surpluses in productivity (B8). Each has a lever.
B30: Champions | C30: CR-020 B9: a Champions sheet built bottom-up from world markets and Pacifica's share of each: the oil trust (Gulf refining and the Asian trade), steel, the assembly-line car industry, chemicals and drugs, electrical equipment on the Pacifican standard, telecom, shipping, San Francisco underwriting, film and aircraft. It adds to GDP, to income from abroad (concessions, plants, royalties) and to the Treasury (the Crown share), and takes a slice off the Union.
B31: Labour | C31: CR-020 B10: migration answers Pacifica's lead. Skilled workers come from the Union, Europe and Asia up to a ceiling of entry places, with their families and later their relatives; workers come for new champion jobs and leave in a slump. The extra talent raises output per resident and the champions; the Union loses what its emigrants would have produced. Only the champions' productivity premium now adds to GDP, since their workers are residents.
B32: The Union | C32: CR-020 B12: the Union is modelled year by year. Its historical output is reduced by the people who are not there (diverted immigrants, talent emigrants and their children), a compounding brain-drain drag, a compounding loss of Pacific trade and gold that grows with Pacifica, the champions' markets, Union citizens away as guest workers, and the 1930-32 German loan crash. This replaces the old fixed drag.
... B38: Not carried over | C38: Sol's bank-by-bank balance sheets, Siberian rail and shipping tonnage tests and foreign settlement deposits. The Siberian campaign keeps Sol's $808m cost and the permanent front keeps his $80m a year.
A40: CR-025: wartime lending, Japanese expansion and capital funding | B40: CR-024: Japan's 1927 rescue | C40: Treasury cash retained, bank capital and yen liquidity separated, monthly FX tested after all liquid reserves, and syndicate matched to actual drawings.
A41: Standing debt now supplies cash at the common issue price. Entente public/private/foreign claims share one repayment convention. | B41: Loan terms | C41: Fixed facility ceiling, 1/3 public and 2/3 private, monthly first-year interest, equal principal 1929-1933; private money reroutes the existing overseas budget.
A42: Sources & uses, War credit, Japan expansion and Capital accounts distinguish cash, claims, valuation and unverified subscribers. | B42: FX and gold | C42: Japanese import buffer is distinct from Pacifica's gold-cover rule. Pacifica records bullion calls and remaining callable settlement balances separately.
A44: 20 Oct: gaps closed | B44: Private capital | C44: Home investment allowance falls to 13% of GDP in 1861-65 and 1870-71, and to 12.4% in 1862; the Baja purchase is paid in five instalments, 1867-71.
B45: Champions | C45: Champion funding sheet: retained cash, Carnegie paid in Pacifica Steel paper ($480m, 1901), local partners' equity (25%), champion bonds sold in Europe (1880-1913) and to the Union and Japan (1919-29). Oil assets abroad are priced at four years' earnings.
B46: Foreign claims | C46: Coupons, the Carnegie yield and partners' earnings are paid out of national income; redemptions are a use of home saving.
B47: Entente | C47: Entente subscribers sheet names the foreign subscribers by source and year, checked against the sources: $3.95bn abroad (none in 1914), $2.85bn from Pacifican savers, $1.7bn from the Treasury.
B48: Japan creditors | C48: The $800m outside Pacifican portfolios is named: London houses $400m, Union banks $250m, continental $100m, regional $50m. Japan's short foreign bank debt is re-timed (21 Oct): $600m in wartime, mostly Pacifican; $1bn in 1919-26 as London and the Union banks return. Japan's Entente subscriptions move to 1917-18.
B49: Numbering | C49: Japan's 1927 rescue is CR-024 and the wartime credit CR-025 (CR-022 and CR-023 are taken).
...

Sheet Levers
A1: Story levers
A2: Every scalar assumption in one place. Pick the case in E4; the Active column feeds the model.
A3: Blue = input · yellow = the main levers · Status says whether the idea is canon; the amount is almost always a model estimate.
B4: Case in use (1 = Story case, 2 = Stress case) | E4: 1 | F4: =IF(E4=1,"Story case","Stress case") -> Story case
B6: Lever | C6: Story case | D6: Stress case | E6: Active | F6: Unit | G6: Status | H6: Basis and notes
B7: — Economy and people —
B8: Residents of California in 1846 | C8: 170000 | D8: 170000 | E8: =IF(case_sel=1,C8,D8) -> 170000 | F8: persons | G8: Model estimate | H8: Californios, Indigenous communities and foreigners; old model used the same figure.
B9: Real non-mining output per resident, 1846 | C9: 150 | D9: 150 | E9: =IF(case_sel=1,C9,D9) -> 150 | F9: 1913 $ | G9: Model estimate | H9: Pastoral Californio economy, a little above the US level of about $125 in 1913 dollars.
B10: Productivity growth after 1895 (× story path) | C10: 1 | D10: 0.75 | E10: =IF(case_sel=1,C10,D10) -> 1 | F10: × | G10: Model estimate | H10: Stress case cuts growth after 1895 by a quarter, like Sol's 25% lower-productivity case.
B11: Immigration after 1895 (× story path) | C11: 1 | D11: 0.8 | E11: =IF(case_sel=1,C11,D11) -> 1 | F11: × | G11: Model estimate | H11: Selective-entry era. Stress case admits a fifth fewer people.
B12: Depression severity 1930-32 (× story slump) | C12: 1 | D12: 1.6 | E12: =IF(case_sel=1,C12,D12) -> 1 | F12: × | G12: Model estimate | H12: Stress case: the 1932 slump is 22% below trend instead of 14%.
B13: Return migration, Asian streams | C13: 0.28 | D13: 0.28 | E13: =IF(case_sel=1,C13,D13) -> 0.28 | F13: share | G13: Model estimate | H13: Share of Chinese, Japanese and Filipino arrivals who later leave. Family migration keeps it lower than the historical 40-50%.
B14: Assisted passage and reception per person | C14: 60 | D14: 60 | E14: =IF(case_sel=1,C14,D14) -> 60 | F14: 1913 $ | G14: Model estimate | H14: Kaiulani's programme: fare, reception and training. Old model: $75 + $12 in 1860 dollars.
B15: Mining value added / gross output | C15: 0.7 | D15: 0.7 | E15: =IF(case_sel=1,C15,D15) -> 0.7 | F15: share | G15: Model estimate | H15: Old model used 0.8.
B16: — Revenue —
B17: Customs collection | C17: 0.9 | D17: 0.9 | E17: =IF(case_sel=1,C17,D17) -> 0.9 | F17: share | G17: Model estimate | H17: Old model value.
B18: Royalty on gold, silver and copper | C18: 0.05 | D18: 0.05 | E18: =IF(case_sel=1,C18,D18) -> 0.05 | F18: share | G18: Canon | H18: Mining Law of 1849: 5% public royalty at the mint and choke points (§5). Applied to all metals here.
B19: State royalty on oil | C19: 0.125 | D19: 0.125 | E19: =IF(case_sel=1,C19,D19) -> 0.125 | F19: share | G19: Model estimate | H19: The state survey found the fields (approved oil programme), so the state keeps a landowner's 1/8 royalty.
B20: State ownership of the Panama canal | C20: 1 | D20: 1 | E20: =IF(case_sel=1,C20,D20) -> 1 | F20: share | G20: Model estimate | H20: Canon: the regency buys the French works in 1889 and completes the canal. Old model assumed 20% public.
B21: Canal operating cost / tolls | C21: 0.4 | D21: 0.4 | E21: =IF(case_sel=1,C21,D21) -> 0.4 | F21: share | G21: Model estimate | H21: Historical Panama: about $10m costs on $25-27m tolls in the late 1920s.
B22: Yield on the Treasury Reserve Fund | C22: 0.04 | D22: 0.04 | E22: =IF(case_sel=1,C22,D22) -> 0.04 | F22: share | G22: Model estimate | H22: Fund holds gold-dollar bonds of partners and the Union.
B23: — Spending —
B24: Cost per active soldier | C24: 700 | D24: 700 | E24: =IF(case_sel=1,C24,D24) -> 700 | F24: 1913 $ | G24: Model estimate | H24: Pay, food, equipment. US Army 1913 ran about $1,100 per soldier; conscript army is cheaper.
B25: Training cost per reservist | C25: 15 | D25: 15 | E25: =IF(case_sel=1,C25,D25) -> 15 | F25: 1913 $ | G25: Model estimate | H25: Defense Law of 1855 reserve liability (§8).
B26: Cost per sailor | C26: 900 | D26: 900 | E26: =IF(case_sel=1,C26,D26) -> 900 | F26: 1913 $ | G26: Model estimate | H26: Pay and keep, at Pacifican wage levels.
B27: Ship maintenance / replacement cost | C27: 0.05 | D27: 0.05 | E27: =IF(case_sel=1,C27,D27) -> 0.05 | F27: share | G27: Model estimate
B28: Bases, yards, training / running costs | C28: 0.15 | D28: 0.15 | E28: =IF(case_sel=1,C28,D28) -> 0.15 | F28: share | G28: Model estimate
B29: Crew of an oil-fired ship vs coal-fired | C29: 0.78 | D29: 0.78 | E29: =IF(case_sel=1,C29,D29) -> 0.78 | F29: × | G29: Model estimate | H29: Oil removes most stokers and coal trimmers, about a fifth of a coal ship's crew.
B30: Fuel cost of own oil vs bought coal | C30: 0.7 | D30: 0.7 | E30: =IF(case_sel=1,C30,D30) -> 0.7 | F30: × | G30: Model estimate | H30: Domestic oil, no colliers or foreign coaling stations.
B31: Pacifica's share of common costs from 1927 | C31: 0.65 | D31: 0.65 | E31: =IF(case_sel=1,C31,D31) -> 0.65 | F31: share | G31: Proposed | H31: Old model working convention (OPEN FIN-13). Japan pays the rest.
B32: — Financing —
B33: Treasury cash at the 1846 founding | C33: 0.05 | D33: 0.05 | E33: =IF(case_sel=1,C33,D33) -> 0.05 | F33: $m | G33: Model estimate | H33: Old model value.
B34: Cash kept / annual receipts | C34: 0.25 | D34: 0.25 | E34: =IF(case_sel=1,C34,D34) -> 0.25 | F34: share | G34: Model estimate | H34: Old model value.
B35: Bond issue price / face | C35: 0.97 | D35: 0.97 | E35: =IF(case_sel=1,C35,D35) -> 0.97 | F35: share | G35: Model estimate
B36: Scheduled debt repayment per year | C36: 0.02 | D36: 0.02 | E36: =IF(case_sel=1,C36,D36) -> 0.02 | F36: share | G36: Model estimate
B37: Share of surplus used to repay debt | C37: 0.8 | D37: 0.8 | E37: =IF(case_sel=1,C37,D37) -> 0.8 | F37: share | G37: Model estimate | H37: The rest of a surplus goes to the Treasury Reserve Fund.
B38: Most new bonds the home market can take / GDP | C38: 0.06 | D38: 0.06 | E38: =IF(case_sel=1,C38,D38) -> 0.06 | F38: share | G38: Model estimate | H38: Old model's market cash commitment limit. Used only in Checks.
B39: Bonds London and other markets will take per year | C39: 10 | D39: 10 | E39: =IF(case_sel=1,C39,D39) -> 10 | F39: $m | G39: Model estimate | H39: Early Pacifica depends on foreign credit (§8-9). Used only in Checks.
B40: — Foreign lending —
B41: Coupon: continental loans (Union, Confederacy, Cuba) | C41: 0.05 | D41: 0.05 | E41: =IF(case_sel=1,C41,D41) -> 0.05 | F41: share | G41: Model estimate
...

Sheet Events
A1: Story events ledger
A2: Every dated commitment from the master storyline that costs or brings in money. One row per event; the annual amount applies in each year from Start to End.
A3: Category decides where the money lands: Purchase, War & operations, Programme, Investment, Subsidy & guarantee, Relief, Bank rescue & capital and Receipt go to the Budget; Loan goes to Loans; Debt assumed adds debt without cash. Investment is spent like a Programme but also counts as development investment, so it raises later output (CR-021 B6). Amounts are Treasury cash in $m; shared or syndicated totals are in the notes.
A4: Rows 6-400 are read by the model (widened from 174 on 27 Oct 2026). Add new events in the first empty row.
A5: ID | B5: Start | C5: End | D5: Event | E5: Category | F5: Loan group | G5: Party | H5: Per year ($m) | I5: Total ($m) | J5: Paid in gold | K5: Story status | L5: Section | M5: Basis of the amount
A6: E01 | B6: 1848 | C6: 1848 | D6: London bondholders' Mexican debt assumed (£3m) | E6: Debt assumed | G6: Britain | H6: 14.6 | I6: =IF(H6="","",H6*(C6-B6+1)) -> 14.6 | J6: No | K6: Canon | L6: §4 | M6: £3m at $4.87
A7: E02 | B7: 1850 | C7: 1851 | D7: San Francisco mint and assay office | E7: Programme | H7: 0.5 | I7: =IF(H7="","",H7*(C7-B7+1)) -> 1 | J7: No | K7: Canon | L7: §5 | M7: Model estimate
A8: E03 | B8: 1853 | C8: 1854 | D8: Walker filibusters: naval supply cut-off | E8: War & operations | H8: 0.3 | I8: =IF(H8="","",H8*(C8-B8+1)) -> 0.6 | J8: No | K8: Canon | L8: §6 | M8: Model estimate
A9: E04 | B9: 1855 | C9: 1861 | D9: Ericsson experimental workshop and turret trials | E9: Programme | H9: 0.4 | I9: =IF(H9="","",H9*(C9-B9+1)) -> 2.8 | J9: No | K9: Canon | L9: §8 | M9: Hulls are in the navy plan
A10: E05 | B10: 1857 | C10: 1858 | D10: Utah War border readiness | E10: War & operations | H10: 0.3 | I10: =IF(H10="","",H10*(C10-B10+1)) -> 0.6 | J10: No | K10: Canon | L10: §8 | M10: Model estimate
A11: E06 | B11: 1860 | C11: 1860 | D11: Pyramid Lake relief force and Washoe crisis | E11: War & operations | H11: 1 | I11: =IF(H11="","",H11*(C11-B11+1)) -> 1 | J11: No | K11: Canon | L11: §8 | M11: Model estimate
A12: E07 | B12: 1861 | C12: 1861 | D12: Northwestern campaign: sea transport and occupation | E12: War & operations | H12: 6 | I12: =IF(H12="","",H12*(C12-B12+1)) -> 6 | J12: No | K12: Canon | L12: §10 | M12: On top of the wartime army in Paths
A13: E08 | B13: 1862 | C13: 1864 | D13: Occupation, interior columns and garrisons | E13: War & operations | H13: 5 | I13: =IF(H13="","",H13*(C13-B13+1)) -> 15 | J13: No | K13: Canon | L13: §10-11 | M13: Model estimate
A14: E09 | B14: 1862 | C14: 1864 | D14: Eastern technical mission and Confederate aid | E14: Subsidy & guarantee | G14: Confederacy | H14: 0.8 | I14: =IF(H14="","",H14*(C14-B14+1)) -> 2.4 | J14: No | K14: Canon | L14: §11 | M14: Logan's mission, Louisiana repairs, Mobile mines
A15: E10 | B15: 1865 | C15: 1865 | D15: Navajo and Apache treaties, peonage compensation | E15: Subsidy & guarantee | H15: 2 | I15: =IF(H15="","",H15*(C15-B15+1)) -> 2 | J15: No | K15: Proposed | L15: §10 | M15: Model estimate
A16: E11 | B16: 1866 | C16: 1872 | D16: Western cession: vendor credit to the Union | E16: Purchase | G16: Union | H16: =union_vendor/7 -> 5.7142857 | I16: =IF(H16="","",H16*(C16-B16+1)) -> 40 | J16: Yes | K16: Proposed | L16: §12 | M16: $40m gold in instalments through 1872
A17: E12 | B17: 1867 | C17: 1867 | D17: Alaska purchase | E17: Purchase | G17: Russia | H17: 7.2 | I17: =IF(H17="","",H17*(C17-B17+1)) -> 7.2 | J17: Yes | K17: Canon | L17: §14 | M17: Historical US price as comparator
A18: E13 | B18: 1867 | C18: 1871 | D18: Baja purchase | E18: Purchase | G18: Mexico | H18: 1 | I18: =IF(H18="","",H18*(C18-B18+1)) -> 5 | J18: Yes | K18: Proposed | L18: §13 | M18: Old model working price ($5m), paid in five annual instalments of $1m, 1867-71 (author's decision, 20 Oct)
A19: E14 | B19: 1867 | C19: 1867 | D19: Treasury loan to the Union | E19: Loan | F19: Continental | G19: Union | H19: 10 | I19: =IF(H19="","",H19*(C19-B19+1)) -> 10 | J19: Yes | K19: Proposed | L19: §12 | M19: Old model L01: $10m syndicate
A20: E15 | B20: 1867 | C20: 1900 | D20: Ocean mail line subsidy (SF-Honolulu-Yokohama-Hong Kong) | E20: Subsidy & guarantee | H20: 1 | I20: =IF(H20="","",H20*(C20-B20+1)) -> 34 | J20: No | K20: Proposed | L20: §14 | M20: Model estimate
A21: E16 | B21: 1868 | C21: 1869 | D21: Fleet guarantee for the Edo transition | E21: War & operations | G21: Japan | H21: 0.5 | I21: =IF(H21="","",H21*(C21-B21+1)) -> 1 | J21: No | K21: Proposed | L21: §14 | M21: Model estimate
A22: E17 | B22: 1870 | C22: 1871 | D22: Gulf squadron, turret ships and mines in Grant's war | E22: War & operations | G22: Confederacy | H22: 6 | I22: =IF(H22="","",H22*(C22-B22+1)) -> 12 | J22: No | K22: Canon | L22: §13 | M22: No field army sent
A23: E18 | B23: 1870 | C23: 1870 | D23: Japan alliance credit (Yokosuka, Takashima) | E23: Loan | F23: Asia | G23: Japan | H23: 5 | I23: =IF(H23="","",H23*(C23-B23+1)) -> 5 | J23: No | K23: Canon | L23: §14 | M23: Old model L02
A24: E19 | B24: 1871 | C24: 1872 | D24: Confederate debt refinanced on customs security | E24: Loan | F24: Continental | G24: Confederacy | H24: 12.5 | I24: =IF(H24="","",H24*(C24-B24+1)) -> 25 | J24: No | K24: Canon | L24: §13 | M24: Old model L03 + L04
A25: E20 | B25: 1871 | C25: 1888 | D25: Replacement of Richmond's Mississippi tolls | E25: Subsidy & guarantee | G25: Confederacy | H25: 1 | I25: =IF(H25="","",H25*(C25-B25+1)) -> 18 | J25: No | K25: Canon | L25: §13 | M25: Model estimate
A26: E21 | B26: 1872 | C26: 1872 | D26: Chinese industrial loans (arsenals, steamships, Kaiping) | E26: Loan | F26: Asia | G26: China | H26: 4 | I26: =IF(H26="","",H26*(C26-B26+1)) -> 4 | J26: No | K26: Proposed | L26: §14 | M26: Public share of a $20m syndicate
A27: E22 | B27: 1873 | C27: 1873 | D27: One-day naval action at Manila Bay | E27: War & operations | G27: Spain | H27: 1.5 | I27: =IF(H27="","",H27*(C27-B27+1)) -> 1.5 | J27: No | K27: Canon | L27: §15 | M27: Model estimate
A28: E23 | B28: 1874 | C28: 1874 | D28: Hawaiian crisis and the Honolulu suppression | E28: War & operations | G28: Hawaii | H28: 1 | I28: =IF(H28="","",H28*(C28-B28+1)) -> 1 | J28: No | K28: Canon | L28: §17 | M28: Model estimate
A29: E24 | B29: 1874 | C29: 1874 | D29: Supplies for Japan's Formosa expedition | E29: War & operations | G29: Japan | H29: 0.5 | I29: =IF(H29="","",H29*(C29-B29+1)) -> 0.5 | J29: No | K29: Proposed | L29: §15 | M29: Model estimate
A30: E25 | B30: 1874 | C30: 1875 | D30: Loan of 1874 to Serrano's Republic, secured on Philippine customs and tobacco | E30: Loan | F30: Europe | G30: Spain | H30: 3 | I30: =IF(H30="","",H30*(C30-B30+1)) -> 6 | J30: No | K30: Approved | L30: §15; CR-029 A7 | M30: Old model L09: $6m; cancelled against the 1876 price (E119)
A31: E26 | B31: 1876 | C31: 1876 | D31: Purchase of the Philippines, Marianas, Carolines and Palau: $20m, paid from the Philippine Redemption Loan | E31: Purchase | G31: Spain | H31: 0 | I31: =IF(H31="","",H31*(C31-B31+1)) -> 0 | J31: Yes | K31: Canon | L31: §15; CR-029 A8 | M31: Off-budget: a Philippine 4% loan of 1876, guaranteed by the Confederation and serviced from Philippine customs; $5.73m of it repays the 1874 loan (E119). The US paid $20m in 1898
A32: E27 | B32: 1876 | C32: 1890 | D32: State oil programme: survey, burner trials, oil locomotives | E32: Programme | H32: 0.3 | I32: =IF(H32="","",H32*(C32-B32+1)) -> 4.5 | J32: No | K32: Approved | L32: §21 | M32: Pico Canyon find; LA and Kern fields found 1885-88
A33: E28 | B33: 1876 | C33: 1879 | D33: North China famine relief | E33: Relief | G33: China | H33: 0.5 | I33: =IF(H33="","",H33*(C33-B33+1)) -> 2 | J33: No | K33: Proposed | L33: §14 | M33: Model estimate
A34: E29 | B34: 1877 | C34: 1914 | D34: Support to the Philippine budget (until the crown of 1914) | E34: Subsidy & guarantee | G34: Philippines | H34: 0.5 | I34: =IF(H34="","",H34*(C34-B34+1)) -> 19 | J34: No | K34: Proposed | L34: §15; CR-029 A10-A11 | M34: Old model transfer; from 1915 the Philippine crown pays a defence contribution (E143-E144)
A35: E30 | B35: 1877 | C35: 1877 | D35: Support for the Meiji government against Satsuma | E35: War & operations | G35: Japan | H35: 0.5 | I35: =IF(H35="","",H35*(C35-B35+1)) -> 0.5 | J35: No | K35: Proposed | L35: §15 | M35: Model estimate
A36: E31 | B36: 1878 | C36: 1878 | D36: Vladivostok maritime action | E36: War & operations | G36: Russia | H36: 6 | I36: =IF(H36="","",H36*(C36-B36+1)) -> 6 | J36: No | K36: Canon | L36: §16 | M36: Model estimate
A37: E32 | B37: 1880 | C37: 1880 | D37: Panama Railroad control and Colombian transit treaty | E37: Purchase | G37: Colombia | H37: 10 | I37: =IF(H37="","",H37*(C37-B37+1)) -> 10 | J37: Yes | K37: Canon | L37: §19 | M37: Old model $10m
A38: E33 | B38: 1880 | C38: 1887 | D38: Korean treaty and neutrality advisers | E38: Programme | G38: Korea | H38: 0.2 | I38: =IF(H38="","",H38*(C38-B38+1)) -> 1.6 | J38: No | K38: Proposed | L38: §14 | M38: Model estimate
A39: E34 | B39: 1884 | C39: 1885 | D39: Keelung squadron protecting the coal trade | E39: War & operations | G39: China | H39: 1 | I39: =IF(H39="","",H39*(C39-B39+1)) -> 2 | J39: No | K39: Proposed | L39: §16 | M39: Model estimate
A40: E35 | B40: 1885 | C40: 1885 | D40: Keelung coal and local rail (public stake) | E40: Loan | F40: Asia | G40: China | H40: 0.6 | I40: =IF(H40="","",H40*(C40-B40+1)) -> 0.6 | J40: No | K40: Proposed | L40: §16 | M40: Old model Q03
...

Sheet Paths
A1: Year-by-year inputs
A2: Time paths behind the model: prices, migration, growth, tax rates, army size and loan terms.
A3: Years run down the page. Blue = input you can change · black = formula · green = link to another sheet. Hover a column heading for its definition.
B4: Prices & people | E4: Gross arrivals (story case) | K4: Prices & people | L4: Economy | N4: Taxes | T4: Spending | Y4: Financing
A5: Year | B5: Price level (1913 = 1) | C5: Natural increase | D5: Residents joining with territory | E5: Arrivals: Americas & Europe | F5: Arrivals: Chinese | G5: Arrivals: Japanese | H5: Arrivals: Filipino | I5: Return migration, Americas & Europe | J5: Share of arrivals assisted | K5: Philippine crown residents (separate) | L5: Real output growth per resident (story) | M5: Output vs trend (slumps) | N5: Dutiable imports / GDP | O5: Average tariff | P5: Domestic taxes / non-mining GDP | Q5: Tax collection | R5: State enterprises & concessions / GDP | S5: Panama canal tolls ($m) | T5: Civil services / GDP | U5: Public works / GDP | V5: Technical & industrial programmes / GDP | W5: Active army | X5: Trained reserves | Y5: Average coupon on public debt | Z5: Coupon on Entente / European loans | AA5: Repayment rate on European loans | AB5: European debtors paying (1/0) | AC5: War year (1/0) | AD5: World monetary gold ($m)
A6: 1846 | B6: 0.74 | C6: -0.008667 | D6: 0 | E6: 2000 | F6: 0 | G6: 0 | H6: 0 | I6: 0.2 | J6: 0.2 | K6: 0 | L6: 0 | M6: 1 | N6: 0.3 | O6: 0.08 | P6: 0.03 | Q6: 0.85 | R6: 0 | S6: 0 | T6: 0.018 | U6: 0.01 | V6: 0 | W6: 500 | X6: 0 | Y6: 0.06 | Z6: 0.05 | AA6: 0.03 | AB6: 1 | AC6: 0 | AD6: 1500
A7: 1847 | B7: 0.74 | C7: -0.008149 | D7: 0 | E7: 3000 | F7: 0 | G7: 0 | H7: 0 | I7: 0.2 | J7: 0.2 | K7: 0 | L7: 0.04 | M7: 1 | N7: 0.2967 | O7: 0.08 | P7: 0.03 | Q7: 0.85 | R7: 2e-05 | S7: 0 | T7: 0.0183 | U7: 0.0108 | V7: 0.0007 | W7: 1500 | X7: 1000 | Y7: 0.0603 | Z7: 0.05 | AA7: 0.03 | AB7: 1 | AC7: 0 | AD7: 1500
A8: 1848 | B8: 0.74 | C8: -0.007642 | D8: 0 | E8: 15000 | F8: 0 | G8: 0 | H8: 0 | I8: 0.2 | J8: 0.2 | K8: 0 | L8: 0.04 | M8: 1 | N8: 0.2933 | O8: 0.08 | P8: 0.03 | Q8: 0.85 | R8: 4e-05 | S8: 0 | T8: 0.0187 | U8: 0.0117 | V8: 0.0013 | W8: 1000 | X8: 2000 | Y8: 0.0605 | Z8: 0.05 | AA8: 0.03 | AB8: 1 | AC8: 0 | AD8: 1500
A9: 1849 | B9: 1.18 | C9: -0.003279 | D9: 0 | E9: 60000 | F9: 300 | G9: 0 | H9: 0 | I9: 0.35 | J9: 0.2 | K9: 0 | L9: 0.04 | M9: 1 | N9: 0.29 | O9: 0.08 | P9: 0.06 | Q9: 0.85 | R9: 6e-05 | S9: 0 | T9: 0.019 | U9: 0.0125 | V9: 0.002 | W9: 1200 | X9: 3000 | Y9: 0.0608 | Z9: 0.05 | AA9: 0.03 | AB9: 1 | AC9: 0 | AD9: 1500
A10: 1850 | B10: 1.1 | C10: 0.006354 | D10: 0 | E10: 50000 | F10: 4000 | G10: 0 | H10: 0 | I10: 0.35 | J10: 0.2 | K10: 0 | L10: 0.04 | M10: 1 | N10: 0.2867 | O10: 0.08 | P10: 0.06 | Q10: 0.85 | R10: 8e-05 | S10: 0 | T10: 0.0193 | U10: 0.0133 | V10: 0.0027 | W10: 1500 | X10: 4000 | Y10: 0.0611 | Z10: 0.05 | AA10: 0.03 | AB10: 1 | AC10: 0 | AD10: 1500
A11: 1851 | B11: 1.02 | C11: 0.010016 | D11: 0 | E11: 40000 | F11: 3000 | G11: 0 | H11: 0 | I11: 0.35 | J11: 0.2 | K11: 0 | L11: 0.04 | M11: 1 | N11: 0.2833 | O11: 0.08 | P11: 0.06 | Q11: 0.85 | R11: 0.0001 | S11: 0 | T11: 0.0197 | U11: 0.0142 | V11: 0.0033 | W11: 2200 | X11: 6000 | Y11: 0.0613 | Z11: 0.05 | AA11: 0.03 | AB11: 1 | AC11: 0 | AD11: 1535
A12: 1852 | B12: 1 | C12: 0.011695 | D12: 0 | E12: 55000 | F12: 20000 | G12: 0 | H12: 0 | I12: 0.35 | J12: 0.4 | K12: 0 | L12: 0.04 | M12: 1 | N12: 0.28 | O12: 0.12 | P12: 0.075 | Q12: 0.85 | R12: 0.00013 | S12: 0 | T12: 0.02 | U12: 0.015 | V12: 0.004 | W12: 3000 | X12: 7000 | Y12: 0.0616 | Z12: 0.05 | AA12: 0.03 | AB12: 1 | AC12: 0 | AD12: 1570
A13: 1853 | B13: 0.99 | C13: 0.018934 | D13: 0 | E13: 40000 | F13: 6000 | G13: 0 | H13: 0 | I13: 0.35 | J13: 0.4 | K13: 0 | L13: 0.04 | M13: 1 | N13: 0.2783 | O13: 0.12 | P13: 0.075 | Q13: 0.85 | R13: 0.00015 | S13: 0 | T13: 0.0202 | U13: 0.0158 | V13: 0.0045 | W13: 3700 | X13: 8000 | Y13: 0.0618 | Z13: 0.05 | AA13: 0.03 | AB13: 1 | AC13: 0 | AD13: 1605
A14: 1854 | B14: 0.97 | C14: 0.020507 | D14: 0 | E14: 35000 | F14: 6000 | G14: 0 | H14: 0 | I14: 0.35 | J14: 0.4 | K14: 0 | L14: 0.04 | M14: 1 | N14: 0.2767 | O14: 0.12 | P14: 0.075 | Q14: 0.85 | R14: 0.00017 | S14: 0 | T14: 0.0203 | U14: 0.0165 | V14: 0.005 | W14: 4300 | X14: 9000 | Y14: 0.0621 | Z14: 0.05 | AA14: 0.03 | AB14: 1 | AC14: 0 | AD14: 1640
A15: 1855 | B15: 0.95 | C15: 0.021664 | D15: 0 | E15: 30000 | F15: 6000 | G15: 0 | H15: 0 | I15: 0.35 | J15: 0.4 | K15: 0 | L15: 0.04 | M15: 1 | N15: 0.275 | O15: 0.12 | P15: 0.085 | Q15: 0.85 | R15: 0.00019 | S15: 0 | T15: 0.0205 | U15: 0.0172 | V15: 0.0055 | W15: 5000 | X15: 10000 | Y15: 0.0624 | Z15: 0.05 | AA15: 0.03 | AB15: 1 | AC15: 0 | AD15: 1675
A16: 1856 | B16: 0.935 | C16: 0.02084 | D16: 72000 | E16: 30000 | F16: 6000 | G16: 0 | H16: 0 | I16: 0.2 | J16: 0.4 | K16: 0 | L16: 0.025 | M16: 1 | N16: 0.2733 | O16: 0.12 | P16: 0.085 | Q16: 0.85 | R16: 0.00021 | S16: 0 | T16: 0.0206 | U16: 0.018 | V16: 0.006 | W16: 6300 | X16: 23000 | Y16: 0.0626 | Z16: 0.05 | AA16: 0.03 | AB16: 1 | AC16: 0 | AD16: 1710
A17: 1857 | B17: 0.92 | C17: 0.020876 | D17: 0 | E17: 30000 | F17: 6000 | G17: 0 | H17: 0 | I17: 0.2 | J17: 0.4 | K17: 0 | L17: 0.025 | M17: 0.97 | N17: 0.2717 | O17: 0.12 | P17: 0.085 | Q17: 0.85 | R17: 0.00023 | S17: 0 | T17: 0.0208 | U17: 0.0181 | V17: 0.0061 | W17: 7700 | X17: 37000 | Y17: 0.0629 | Z17: 0.05 | AA17: 0.03 | AB17: 1 | AC17: 0 | AD17: 1745
... A92: 1932 | B92: 1.22 | C92: 0.016532 | D92: 0 | E92: 30000 | F92: 12000 | G92: 12000 | H92: 8000 | I92: 0.2 | J92: 0.3 | K92: 13218388 | L92: 0 | M92: 0.86 | N92: 0.13 | O92: 0.12 | P92: 0.085 | Q92: 0.8 | R92: 0.002 | S92: 22 | T92: 0.047 | U92: 0.026 | V92: 0.008 | W92: 42000 | X92: 220000 | Y92: 0.05 | Z92: 0.033 | AA92: 0 | AB92: 0 | AC92: 0 | AD92: 11900

Sheet People
A1: Population
A2: Residents of core Pacifica: births, territory, and four migration streams.
A3: Years run down the page. Blue = input you can change · black = formula · green = link to another sheet. Hover a column heading for its definition.
B4: Residents | E4: Arrivals | L4: Residents | N4: Asian-origin residents | T4: Programme | V4: With the Gulf | Y4: Memo (not in totals)
A5: Year | B5: Residents at start of year | C5: Join with territory | D5: Natural increase | E5: Arrivals: Americas & Europe | F5: Arrivals: Chinese | G5: Arrivals: Japanese | H5: Arrivals: Filipino | I5: Leave again | J5: Extra arrivals drawn by Pacifica's lead | K5: Net migration | L5: Residents at end of year | M5: Growth | N5: Chinese-Pacificans | O5: Japanese-Pacificans | P5: Filipino-Pacificans | Q5: Settled guest workers of Asian origin (now in N-P) | R5: Asian talent migrants and families (now in N-P) | S5: Asian-origin share | T5: Assisted arrivals | U5: Philippine crown residents (separate) | V5: Gulf Republic residents (once a member) | W5: All residents incl. the Gulf | X5: Everyone present, incl. guest workers | Y5: Native Hawaiians (memo, population model) | Z5: Native Californians (memo, population model)
A6: 1846 | B6: =pop_1846 -> 170000 | C6: =Paths!D6 -> 0 | D6: =B6*Paths!C6 -> -1473.39 | E6: =Paths!E6*IF($A6>=1896,mig_scale,1)*IF(AND($A6>=1848,$A6<=1860),dem01_mult,1) -> 2000 | F6: =Paths!F6*IF($A6>=1896,mig_scale,1)*IF(AND($A6>=1848,$A6<=1860),dem01_mult,1) -> 0 | G6: =Paths!G6*IF($A6>=1896,mig_scale,1) -> 0 | H6: =Paths!H6*IF($A6>=1896,mig_scale,1) -> 0 | I6: =E6*Paths!I6+(F6+G6+H6)*dep_asia -> 400 | J6: =Labour!AL6 -> 0 | K6: =SUM(E6:H6)-I6+J6 -> 1600 | L6: =B6+C6+D6+K6 -> 170126.61 | M6: =IF(B6>0,L6/B6-1,0) -> 0.00074476471 | N6: =0 -> 0 | O6: =0 -> 0 | P6: =0 -> 0 | Q6: =0 -> 0 | R6: =0 -> 0 | S6: =(N6+O6+P6+Q6+R6)/L6 -> 0 | T6: =SUM(E6:H6)*Paths!J6 -> 400 | U6: =Paths!K6 -> 0 | V6: =IF(Gulf!E6=1,Gulf!B6,0) -> 0 | W6: =L6+V6 -> 170126.61 | X6: =W6+Labour!L6 -> 170126.61 | Y6: 0 | Z6: 148391
A7: 1847 | B7: =L6 -> 170126.61 | C7: =Paths!D7 -> 0 | D7: =B7*Paths!C7 -> -1386.3617 | E7: =Paths!E7*IF($A7>=1896,mig_scale,1)*IF(AND($A7>=1848,$A7<=1860),dem01_mult,1) -> 3000 | F7: =Paths!F7*IF($A7>=1896,mig_scale,1)*IF(AND($A7>=1848,$A7<=1860),dem01_mult,1) -> 0 | G7: =Paths!G7*IF($A7>=1896,mig_scale,1) -> 0 | H7: =Paths!H7*IF($A7>=1896,mig_scale,1) -> 0 | I7: =E7*Paths!I7+(F7+G7+H7)*dep_asia -> 600 | J7: =Labour!AL7 -> 0 | K7: =SUM(E7:H7)-I7+J7 -> 2400 | L7: =B7+C7+D7+K7 -> 171140.25 | M7: =IF(B7>0,L7/B7-1,0) -> 0.0059581406 | N7: =N6*(1+Paths!C7)+F7*(1-dep_asia)+Labour!AL7*IF($A7>=xo_year,xo_cn2,xo_cn1) -> 0 | O7: =O6*(1+Paths!C7)+G7*(1-dep_asia)+Labour!AL7*IF($A7>=xo_year,xo_jp2,xo_jp1) -> 0 | P7: =P6*(1+Paths!C7)+H7*(1-dep_asia)+Labour!AL7*IF($A7>=xo_year,xo_ph2,xo_ph1) -> 0 | Q7: =0 -> 0 | R7: =0 -> 0 | S7: =(N7+O7+P7+Q7+R7)/L7 -> 0 | T7: =SUM(E7:H7)*Paths!J7 -> 600 | U7: =Paths!K7 -> 0 | V7: =IF(Gulf!E7=1,Gulf!B7,0) -> 0 | W7: =L7+V7 -> 171140.25 | X7: =W7+Labour!L7 -> 171140.25 | Y7: 0 | Z7: 146799
A8: 1848 | B8: =L7 -> 171140.25 | C8: =Paths!D8 -> 0 | D8: =B8*Paths!C8 -> -1307.8538 | E8: =Paths!E8*IF($A8>=1896,mig_scale,1)*IF(AND($A8>=1848,$A8<=1860),dem01_mult,1) -> 31500 | F8: =Paths!F8*IF($A8>=1896,mig_scale,1)*IF(AND($A8>=1848,$A8<=1860),dem01_mult,1) -> 0 | G8: =Paths!G8*IF($A8>=1896,mig_scale,1) -> 0 | H8: =Paths!H8*IF($A8>=1896,mig_scale,1) -> 0 | I8: =E8*Paths!I8+(F8+G8+H8)*dep_asia -> 6300 | J8: =Labour!AL8 -> 0 | K8: =SUM(E8:H8)-I8+J8 -> 25200 | L8: =B8+C8+D8+K8 -> 195032.39 | M8: =IF(B8>0,L8/B8-1,0) -> 0.13960565 | N8: =N7*(1+Paths!C8)+F8*(1-dep_asia)+Labour!AL8*IF($A8>=xo_year,xo_cn2,xo_cn1) -> 0 | O8: =O7*(1+Paths!C8)+G8*(1-dep_asia)+Labour!AL8*IF($A8>=xo_year,xo_jp2,xo_jp1) -> 0 | P8: =P7*(1+Paths!C8)+H8*(1-dep_asia)+Labour!AL8*IF($A8>=xo_year,xo_ph2,xo_ph1) -> 0 | Q8: =0 -> 0 | R8: =0 -> 0 | S8: =(N8+O8+P8+Q8+R8)/L8 -> 0 | T8: =SUM(E8:H8)*Paths!J8 -> 6300 | U8: =Paths!K8 -> 0 | V8: =IF(Gulf!E8=1,Gulf!B8,0) -> 0 | W8: =L8+V8 -> 195032.39 | X8: =W8+Labour!L8 -> 195032.39 | Y8: 0 | Z8: 145225
